<sdf version='1.6'>
  <world name='default'>
    <light name='sun' type='directional'>
      <cast_shadows>1</cast_shadows>
      <pose frame=''>0 0 10 0 -0 0</pose>
      <diffuse>0.8 0.8 0.8 1</diffuse>
      <specular>0.2 0.2 0.2 1</specular>
      <attenuation>
        <range>1000</range>
        <constant>0.9</constant>
        <linear>0.01</linear>
        <quadratic>0.001</quadratic>
      </attenuation>
      <direction>-0.5 0.1 -0.9</direction>
    </light>
    <model name='ground_plane'>
      <static>1</static>
      <link name='link'>
        <collision name='collision'>
          <geometry>
            <plane>
              <normal>0 0 1</normal>
              <size>100 100</size>
            </plane>
          </geometry>
          <surface>
            <friction>
              <ode>
                <mu>100</mu>
                <mu2>50</mu2>
              </ode>
              <torsional>
                <ode/>
              </torsional>
            </friction>
            <contact>
              <ode/>
            </contact>
            <bounce/>
          </surface>
          <max_contacts>10</max_contacts>
        </collision>
        <visual name='visual'>
          <cast_shadows>0</cast_shadows>
          <geometry>
            <plane>
              <normal>0 0 1</normal>
              <size>100 100</size>
            </plane>
          </geometry>
          <material>
            <script>
              <uri>file://media/materials/scripts/gazebo.material</uri>
              <name>Gazebo/Grey</name>
            </script>
          </material>
        </visual>
        <self_collide>0</self_collide>
        <enable_wind>0</enable_wind>
        <kinematic>0</kinematic>
      </link>
    </model>
    <physics name='default_physics' default='0' type='ode'>
      <real_time_update_rate>1000</real_time_update_rate>
      <max_step_size>0.001</max_step_size>
      <real_time_factor>1</real_time_factor>
    </physics>
    <gravity>0 0 -9.81</gravity>
    <magnetic_field>6e-06 2.3e-05 -4.2e-05</magnetic_field>
    <atmosphere type='adiabatic'/>
    <scene>
      <ambient>0.4 0.4 0.4 1</ambient>
      <background>0.7 0.7 0.7 1</background>
      <shadows>1</shadows>
    </scene>
    <wind/>
    <spherical_coordinates>
      <surface_model>EARTH_WGS84</surface_model>
      <latitude_deg>0</latitude_deg>
      <longitude_deg>0</longitude_deg>
      <elevation>0</elevation>
      <heading_deg>0</heading_deg>
    </spherical_coordinates>
    <model name='niryo_one'>
      <link name='ground_link'>
        <pose frame=''>0 0 0 0 -0 0</pose>
        <inertial>
          <pose frame=''>0 0 0 0 -0 0</pose>
          <mass>100</mass>
          <inertia>
            <ixx>0.21666</ixx>
            <ixy>0</ixy>
            <ixz>0</ixz>
            <iyy>0.32666</iyy>
            <iyz>0</iyz>
            <izz>0.21666</izz>
          </inertia>
        </inertial>
        <collision name='ground_link_fixed_joint_lump__base_link_collision'>
          <pose frame=''>0 0 0 0 -0 0</pose>
          <geometry>
            <mesh>
              <scale>1 1 1</scale>
              <uri>/home/ros/catkin_ws/src/niryo_one_ros/niryo_one_description/meshes/v2/stl/base_link.stl</uri>
            </mesh>
          </geometry>
          <surface>
            <contact>
              <ode/>
            </contact>
            <friction>
              <ode/>
              <torsional>
                <ode/>
              </torsional>
            </friction>
            <bounce/>
          </surface>
          <max_contacts>10</max_contacts>
        </collision>
        <visual name='ground_link_fixed_joint_lump__base_link_visual'>
          <pose frame=''>0 0 0 0 -0 0</pose>
          <geometry>
            <mesh>
              <scale>1 1 1</scale>
              <uri>/home/ros/catkin_ws/src/niryo_one_ros/niryo_one_description/meshes/v2/collada/base_link.dae</uri>
            </mesh>
          </geometry>
          <material>
            <script>
              <uri>__default__</uri>
              <name>__default__</name>
            </script>
          </material>
        </visual>
        <velocity_decay/>
        <gravity>1</gravity>
        <velocity_decay/>
        <self_collide>0</self_collide>
        <enable_wind>0</enable_wind>
        <kinematic>0</kinematic>
      </link>
      <link name='shoulder_link'>
        <pose frame=''>0 0 0.103 0 -0 0</pose>
        <inertial>
          <pose frame=''>0 0 0 0 -0 0</pose>
          <mass>0.4</mass>
          <inertia>
            <ixx>0.00221</ixx>
            <ixy>0</ixy>
            <ixz>0</ixz>
            <iyy>0</iyy>
            <iyz>0</iyz>
            <izz>0.00221</izz>
          </inertia>
        </inertial>
        <collision name='shoulder_link_collision'>
          <pose frame=''>0 0 0 0 -0 0</pose>
          <geometry>
            <mesh>
              <scale>1 1 1</scale>
              <uri>/home/ros/catkin_ws/src/niryo_one_ros/niryo_one_description/meshes/v2/stl/shoulder_link.stl</uri>
            </mesh>
          </geometry>
          <surface>
            <contact>
              <ode/>
            </contact>
            <friction>
              <ode/>
              <torsional>
                <ode/>
              </torsional>
            </friction>
            <bounce/>
          </surface>
          <max_contacts>10</max_contacts>
        </collision>
        <visual name='shoulder_link_visual'>
          <pose frame=''>0 0 0 0 -0 0</pose>
          <geometry>
            <mesh>
              <scale>1 1 1</scale>
              <uri>/home/ros/catkin_ws/src/niryo_one_ros/niryo_one_description/meshes/v2/collada/shoulder_link.dae</uri>
            </mesh>
          </geometry>
          <material>
            <script>
              <uri>__default__</uri>
              <name>__default__</name>
            </script>
          </material>
        </visual>
        <gravity>0</gravity>
        <velocity_decay/>
        <self_collide>0</self_collide>
        <enable_wind>0</enable_wind>
        <kinematic>0</kinematic>
      </link>
      <joint name='joint_1' type='revolute'>
        <child>shoulder_link</child>
        <parent>ground_link</parent>
        <axis>
          <xyz>0 0 1</xyz>
          <limit>
            <lower>-3.05433</lower>
            <upper>3.05433</upper>
            <effort>1</effort>
            <velocity>1</velocity>
          </limit>
          <dynamics>
            <spring_reference>0</spring_reference>
            <spring_stiffness>0</spring_stiffness>
          </dynamics>
          <use_parent_model_frame>1</use_parent_model_frame>
        </axis>
      </joint>
      <link name='arm_link'>
        <pose frame=''>0 0 0.183 -1.57079 -1.57079 3.14159</pose>
        <inertial>
          <pose frame=''>0 0 0 0 -0 0</pose>
          <mass>0.4</mass>
          <inertia>
            <ixx>0.0022</ixx>
            <ixy>0</ixy>
            <ixz>0</ixz>
            <iyy>0</iyy>
            <iyz>0</iyz>
            <izz>0.0022</izz>
          </inertia>
        </inertial>
        <collision name='arm_link_collision'>
          <pose frame=''>0 0 0 0 -0 0</pose>
          <geometry>
            <mesh>
              <scale>1 1 1</scale>
              <uri>/home/ros/catkin_ws/src/niryo_one_ros/niryo_one_description/meshes/v2/stl/arm_link.stl</uri>
            </mesh>
          </geometry>
          <surface>
            <contact>
              <ode/>
            </contact>
            <friction>
              <ode/>
              <torsional>
                <ode/>
              </torsional>
            </friction>
            <bounce/>
          </surface>
          <max_contacts>10</max_contacts>
        </collision>
        <visual name='arm_link_visual'>
          <pose frame=''>0 0 0 0 -0 0</pose>
          <geometry>
            <mesh>
              <scale>1 1 1</scale>
              <uri>/home/ros/catkin_ws/src/niryo_one_ros/niryo_one_description/meshes/v2/collada/arm_link.dae</uri>
            </mesh>
          </geometry>
          <material>
            <script>
              <uri>__default__</uri>
              <name>__default__</name>
            </script>
          </material>
        </visual>
        <gravity>0</gravity>
        <velocity_decay/>
        <self_collide>0</self_collide>
        <enable_wind>0</enable_wind>
        <kinematic>0</kinematic>
      </link>
      <joint name='joint_2' type='revolute'>
        <child>arm_link</child>
        <parent>shoulder_link</parent>
        <axis>
          <xyz>0 -1 -0</xyz>
          <limit>
            <lower>-1.91986</lower>
            <upper>0.640187</upper>
            <effort>1</effort>
            <velocity>1</velocity>
          </limit>
          <dynamics>
            <spring_reference>0</spring_reference>
            <spring_stiffness>0</spring_stiffness>
          </dynamics>
          <use_parent_model_frame>1</use_parent_model_frame>
        </axis>
      </joint>
      <link name='elbow_link'>
        <pose frame=''>-0 -0 0.393 1.5708 -0 0</pose>
        <inertial>
          <pose frame=''>0 0 0 0 -0 0</pose>
          <mass>0.4</mass>
          <inertia>
            <ixx>0.0022</ixx>
            <ixy>0</ixy>
            <ixz>0</ixz>
            <iyy>0</iyy>
            <iyz>0</iyz>
            <izz>0.022</izz>
          </inertia>
        </inertial>
        <collision name='elbow_link_collision'>
          <pose frame=''>0 0 0 0 -0 0</pose>
          <geometry>
            <mesh>
              <scale>1 1 1</scale>
              <uri>/home/ros/catkin_ws/src/niryo_one_ros/niryo_one_description/meshes/v2/stl/elbow_link.stl</uri>
            </mesh>
          </geometry>
          <surface>
            <contact>
              <ode/>
            </contact>
            <friction>
              <ode/>
              <torsional>
                <ode/>
              </torsional>
            </friction>
            <bounce/>
          </surface>
          <max_contacts>10</max_contacts>
        </collision>
        <visual name='elbow_link_visual'>
          <pose frame=''>0 0 0 0 -0 0</pose>
          <geometry>
            <mesh>
              <scale>1 1 1</scale>
              <uri>/home/ros/catkin_ws/src/niryo_one_ros/niryo_one_description/meshes/v2/collada/elbow_link.dae</uri>
            </mesh>
          </geometry>
          <material>
            <script>
              <uri>__default__</uri>
              <name>__default__</name>
            </script>
          </material>
        </visual>
        <gravity>0</gravity>
        <velocity_decay/>
        <self_collide>0</self_collide>
        <enable_wind>0</enable_wind>
        <kinematic>0</kinematic>
      </link>
      <joint name='joint_3' type='revolute'>
        <child>elbow_link</child>
        <parent>arm_link</parent>
        <axis>
          <xyz>0 -1 -0</xyz>
          <limit>
            <lower>-1.39749</lower>
            <upper>1.5708</upper>
            <effort>1</effort>
            <velocity>1</velocity>
          </limit>
          <dynamics>
            <spring_reference>0</spring_reference>
            <spring_stiffness>0</spring_stiffness>
          </dynamics>
          <use_parent_model_frame>1</use_parent_model_frame>
        </axis>
      </joint>
      <link name='forearm_link'>
        <pose frame=''>0.0415 0 0.423 1.5708 -0 1.5708</pose>
        <inertial>
          <pose frame=''>0 0 0 0 -0 0</pose>
          <mass>0.4</mass>
          <inertia>
            <ixx>0.0022</ixx>
            <ixy>0</ixy>
            <ixz>0</ixz>
            <iyy>1</iyy>
            <iyz>0</iyz>
            <izz>0.0022</izz>
          </inertia>
        </inertial>
        <collision name='forearm_link_collision'>
          <pose frame=''>0 0 0 0 -0 0</pose>
          <geometry>
            <mesh>
              <scale>1 1 1</scale>
              <uri>/home/ros/catkin_ws/src/niryo_one_ros/niryo_one_description/meshes/v2/stl/forearm_link.stl</uri>
            </mesh>
          </geometry>
          <surface>
            <contact>
              <ode/>
            </contact>
            <friction>
              <ode/>
              <torsional>
                <ode/>
              </torsional>
            </friction>
            <bounce/>
          </surface>
          <max_contacts>10</max_contacts>
        </collision>
        <visual name='forearm_link_visual'>
          <pose frame=''>0 0 0 0 -0 0</pose>
          <geometry>
            <mesh>
              <scale>1 1 1</scale>
              <uri>/home/ros/catkin_ws/src/niryo_one_ros/niryo_one_description/meshes/v2/collada/forearm_link.dae</uri>
            </mesh>
          </geometry>
          <material>
            <script>
              <uri>__default__</uri>
              <name>__default__</name>
            </script>
          </material>
        </visual>
        <gravity>0</gravity>
        <velocity_decay/>
        <self_collide>0</self_collide>
        <enable_wind>0</enable_wind>
        <kinematic>0</kinematic>
      </link>
      <joint name='joint_4' type='revolute'>
        <child>forearm_link</child>
        <parent>elbow_link</parent>
        <axis>
          <xyz>1 0 0</xyz>
          <limit>
            <lower>-3.05433</lower>
            <upper>3.05433</upper>
            <effort>1</effort>
            <velocity>1</velocity>
          </limit>
          <dynamics>
            <spring_reference>0</spring_reference>
            <spring_stiffness>0</spring_stiffness>
          </dynamics>
          <use_parent_model_frame>1</use_parent_model_frame>
        </axis>
      </joint>
      <link name='wrist_link'>
        <pose frame=''>0.2215 0 0.423 1.5708 -0 0</pose>
        <inertial>
          <pose frame=''>0 0 0 0 -0 0</pose>
          <mass>0.2</mass>
          <inertia>
            <ixx>0.0011</ixx>
            <ixy>0</ixy>
            <ixz>0</ixz>
            <iyy>0</iyy>
            <iyz>0</iyz>
            <izz>0.0011</izz>
          </inertia>
        </inertial>
        <collision name='wrist_link_collision'>
          <pose frame=''>0 0 0 0 -0 0</pose>
          <geometry>
            <mesh>
              <scale>1 1 1</scale>
              <uri>/home/ros/catkin_ws/src/niryo_one_ros/niryo_one_description/meshes/v2/stl/wrist_link.stl</uri>
            </mesh>
          </geometry>
          <surface>
            <contact>
              <ode/>
            </contact>
            <friction>
              <ode/>
              <torsional>
                <ode/>
              </torsional>
            </friction>
            <bounce/>
          </surface>
          <max_contacts>10</max_contacts>
        </collision>
        <visual name='wrist_link_visual'>
          <pose frame=''>0 0 0 0 -0 0</pose>
          <geometry>
            <mesh>
              <scale>1 1 1</scale>
              <uri>/home/ros/catkin_ws/src/niryo_one_ros/niryo_one_description/meshes/v2/collada/wrist_link.dae</uri>
            </mesh>
          </geometry>
          <material>
            <script>
              <uri>__default__</uri>
              <name>__default__</name>
            </script>
          </material>
        </visual>
        <gravity>0</gravity>
        <velocity_decay/>
        <self_collide>0</self_collide>
        <enable_wind>0</enable_wind>
        <kinematic>0</kinematic>
      </link>
      <joint name='joint_5' type='revolute'>
        <child>wrist_link</child>
        <parent>forearm_link</parent>
        <axis>
          <xyz>0 -1 -0</xyz>
          <limit>
            <lower>-1.74533</lower>
            <upper>1.91986</upper>
            <effort>1</effort>
            <velocity>1</velocity>
          </limit>
          <dynamics>
            <spring_reference>0</spring_reference>
            <spring_stiffness>0</spring_stiffness>
          </dynamics>
          <use_parent_model_frame>1</use_parent_model_frame>
        </axis>
      </joint>
      <link name='hand_link'>
        <pose frame=''>0.2379 0 0.4175 1.5708 -0 1.5708</pose>
        <inertial>
          <pose frame=''>0 -0.009286 0.023071 0 -0 0</pose>
          <mass>0.35</mass>
          <inertia>
            <ixx>1.00025</ixx>
            <ixy>7.39164e-22</ixy>
            <ixz>4.25274e-16</ixz>
            <iyy>1.00024</iyy>
            <iyz>2.99929e-05</iyz>
            <izz>1.00026</izz>
          </inertia>
        </inertial>
        <collision name='hand_link_collision'>
          <pose frame=''>0 0 0 0 -0 0</pose>
          <geometry>
            <mesh>
              <scale>1 1 1</scale>
              <uri>/home/ros/catkin_ws/src/niryo_one_ros/niryo_one_description/meshes/v2/stl/hand_link.stl</uri>
            </mesh>
          </geometry>
          <surface>
            <contact>
              <ode/>
            </contact>
            <friction>
              <ode/>
              <torsional>
                <ode/>
              </torsional>
            </friction>
            <bounce/>
          </surface>
          <max_contacts>10</max_contacts>
        </collision>
        <collision name='hand_link_fixed_joint_lump__gripper_base_link_collision_1'>
          <pose frame=''>0.01 -0.033 0.0823 -3.14159 0.001593 3.14</pose>
          <geometry>
            <mesh>
              <scale>0.001 0.001 0.001</scale>
              <uri>/home/ros/catkin_ws/src/niryo_one_ros/niryo_one_description/meshes/v2/stl/G2_MainSupport.STL</uri>
            </mesh>
          </geometry>
          <surface>
            <contact>
              <ode/>
            </contact>
            <friction>
              <ode/>
              <torsional>
                <ode/>
              </torsional>
            </friction>
            <bounce/>
          </surface>
          <max_contacts>10</max_contacts>
        </collision>
        <visual name='hand_link_visual'>
          <pose frame=''>0 0 0 0 -0 0</pose>
          <geometry>
            <mesh>
              <scale>1 1 1</scale>
              <uri>/home/ros/catkin_ws/src/niryo_one_ros/niryo_one_description/meshes/v2/collada/hand_link.dae</uri>
            </mesh>
          </geometry>
          <material>
            <script>
              <uri>__default__</uri>
              <name>__default__</name>
            </script>
          </material>
        </visual>
        <visual name='hand_link_fixed_joint_lump__gripper_base_link_visual_1'>
          <pose frame=''>0.01 -0.033 0.0823 -3.14159 0.001593 3.14</pose>
          <geometry>
            <mesh>
              <scale>0.001 0.001 0.001</scale>
              <uri>/home/ros/catkin_ws/src/niryo_one_ros/niryo_one_description/meshes/v2/stl/G2_MainSupport.STL</uri>
            </mesh>
          </geometry>
          <material>
            <script>
              <name>Gazebo/Black</name>
              <uri>file://media/materials/scripts/gazebo.material</uri>
            </script>
          </material>
        </visual>
        <velocity_decay/>
        <velocity_decay/>
        <gravity>1</gravity>
        <velocity_decay/>
        <self_collide>0</self_collide>
        <enable_wind>0</enable_wind>
        <kinematic>0</kinematic>
      </link>
      <joint name='joint_6' type='revolute'>
        <child>hand_link</child>
        <parent>wrist_link</parent>
        <axis>
          <xyz>1 0 -0</xyz>
          <limit>
            <lower>-2.57436</lower>
            <upper>2.57436</upper>
            <effort>1</effort>
            <velocity>1</velocity>
          </limit>
          <dynamics>
            <spring_reference>0</spring_reference>
            <spring_stiffness>0</spring_stiffness>
          </dynamics>
          <use_parent_model_frame>1</use_parent_model_frame>
        </axis>
      </joint>
      <link name='gripper_gear_left_link'>
        <pose frame=''>0.2752 -0.016 0.4045 -1.5708 -0 -1.5708</pose>
        <inertial>
          <pose frame=''>0 0 0 0 -0 0</pose>
          <mass>0.25</mass>
          <inertia>
            <ixx>0.000166667</ixx>
            <ixy>0</ixy>
            <ixz>0</ixz>
            <iyy>0.000166667</iyy>
            <iyz>0</iyz>
            <izz>0.00025</izz>
          </inertia>
        </inertial>
        <collision name='gripper_gear_left_link_collision'>
          <pose frame=''>0 0 0 0 -0 0</pose>
          <geometry>
            <mesh>
              <scale>0.001 0.001 0.001</scale>
              <uri>/home/ros/catkin_ws/src/niryo_one_ros/niryo_one_description/meshes/v2/stl/G2_GearLeft.STL</uri>
            </mesh>
          </geometry>
          <max_contacts>10</max_contacts>
          <surface>
            <contact>
              <ode/>
            </contact>
            <bounce/>
            <friction>
              <torsional>
                <ode/>
              </torsional>
              <ode/>
            </friction>
          </surface>
        </collision>
        <visual name='gripper_gear_left_link_visual'>
          <pose frame=''>-0.025 0.02 0.045 3.14 -0 0</pose>
          <geometry>
            <mesh>
              <scale>0.001 0.001 0.001</scale>
              <uri>/home/ros/catkin_ws/src/niryo_one_ros/niryo_one_description/meshes/v2/stl/G2_GearLeft.STL</uri>
            </mesh>
          </geometry>
        </visual>
        <self_collide>0</self_collide>
        <enable_wind>0</enable_wind>
        <kinematic>0</kinematic>
      </link>
      <joint name='gripper_gear_left_joint' type='revolute'>
        <child>gripper_gear_left_link</child>
        <parent>hand_link</parent>
        <axis>
          <xyz>-0 0 1</xyz>
          <limit>
            <lower>-1.2</lower>
            <upper>0</upper>
            <effort>1000</effort>
            <velocity>0.5</velocity>
          </limit>
          <dynamics>
            <spring_reference>0</spring_reference>
            <spring_stiffness>0</spring_stiffness>
          </dynamics>
          <use_parent_model_frame>1</use_parent_model_frame>
        </axis>
        <physics>
          <ode>
            <implicit_spring_damper>1</implicit_spring_damper>
            <cfm_damping>1</cfm_damping>
            <limit>
              <cfm>0</cfm>
              <erp>0.2</erp>
            </limit>
          </ode>
        </physics>
      </joint>
      <link name='gripper_left_finger_base_link'>
        <pose frame=''>0.3102 -0.026 0.4045 -1.5708 0 -1.55334</pose>
        <inertial>
          <pose frame=''>0 0 0 0 -0 0</pose>
          <mass>0.02</mass>
          <inertia>
            <ixx>6.66667e-07</ixx>
            <ixy>0</ixy>
            <ixz>0</ixz>
            <iyy>6.66667e-07</iyy>
            <iyz>0</iyz>
            <izz>1e-06</izz>
          </inertia>
        </inertial>
        <collision name='gripper_left_finger_base_link_collision'>
          <pose frame=''>0 0 0 0 -0 0</pose>
          <geometry>
            <mesh>
              <scale>0.001 0.001 0.001</scale>
              <uri>/home/ros/catkin_ws/src/niryo_one_ros/niryo_one_description/meshes/v2/stl/G2_Clamp.STL</uri>
            </mesh>
          </geometry>
          <max_contacts>10</max_contacts>
          <surface>
            <contact>
              <ode/>
            </contact>
            <bounce/>
            <friction>
              <torsional>
                <ode/>
              </torsional>
              <ode/>
            </friction>
          </surface>
        </collision>
        <visual name='gripper_left_finger_base_link_visual'>
          <pose frame=''>-0.001 -0.007 0.011 3.14159 0.001593 3.14159</pose>
          <geometry>
            <mesh>
              <scale>0.001 0.001 0.001</scale>
              <uri>/home/ros/catkin_ws/src/niryo_one_ros/niryo_one_description/meshes/v2/stl/G2_Clamp.STL</uri>
            </mesh>
          </geometry>
        </visual>
        <self_collide>0</self_collide>
        <enable_wind>0</enable_wind>
        <kinematic>0</kinematic>
      </link>
      <joint name='gripper_left_finger_base_joint' type='revolute'>
        <child>gripper_left_finger_base_link</child>
        <parent>gripper_gear_left_link</parent>
        <axis>
          <xyz>-0 0 1</xyz>
          <limit>
            <lower>-1.2</lower>
            <upper>1.2</upper>
            <effort>1000</effort>
            <velocity>0.5</velocity>
          </limit>
          <dynamics>
            <damping>0.7</damping>
            <friction>0</friction>
            <spring_reference>0</spring_reference>
            <spring_stiffness>0</spring_stiffness>
          </dynamics>
          <use_parent_model_frame>1</use_parent_model_frame>
        </axis>
        <physics>
          <ode>
            <implicit_spring_damper>1</implicit_spring_damper>
            <cfm_damping>1</cfm_damping>
            <limit>
              <cfm>0</cfm>
              <erp>0.2</erp>
            </limit>
          </ode>
        </physics>
      </joint>
      <link name='gripper_gear_right_link'>
        <pose frame=''>0.2752 0.003 0.4045 -1.5708 -0 -1.5708</pose>
        <inertial>
          <pose frame=''>0 0 0 0 -0 0</pose>
          <mass>0.25</mass>
          <inertia>
            <ixx>0.000166667</ixx>
            <ixy>0</ixy>
            <ixz>0</ixz>
            <iyy>0.000166667</iyy>
            <iyz>0</iyz>
            <izz>0.00025</izz>
          </inertia>
        </inertial>
        <collision name='gripper_gear_right_link_collision'>
          <pose frame=''>0 0 0 0 -0 0</pose>
          <geometry>
            <mesh>
              <scale>0.001 0.001 0.001</scale>
              <uri>/home/ros/catkin_ws/src/niryo_one_ros/niryo_one_description/meshes/v2/stl/G2_GearRight.STL</uri>
            </mesh>
          </geometry>
          <max_contacts>10</max_contacts>
          <surface>
            <contact>
              <ode/>
            </contact>
            <bounce/>
            <friction>
              <torsional>
                <ode/>
              </torsional>
              <ode/>
            </friction>
          </surface>
        </collision>
        <visual name='gripper_gear_right_link_visual'>
          <pose frame=''>-0.008 0.02 0.045 3.14 -0 0</pose>
          <geometry>
            <mesh>
              <scale>0.001 0.001 0.001</scale>
              <uri>/home/ros/catkin_ws/src/niryo_one_ros/niryo_one_description/meshes/v2/stl/G2_GearRight.STL</uri>
            </mesh>
          </geometry>
        </visual>
        <self_collide>0</self_collide>
        <enable_wind>0</enable_wind>
        <kinematic>0</kinematic>
      </link>
      <joint name='gripper_gear_right_joint' type='revolute'>
        <child>gripper_gear_right_link</child>
        <parent>hand_link</parent>
        <axis>
          <xyz>-0 0 1</xyz>
          <limit>
            <lower>0</lower>
            <upper>1.2</upper>
            <effort>1000</effort>
            <velocity>0.5</velocity>
          </limit>
          <dynamics>
            <spring_reference>0</spring_reference>
            <spring_stiffness>0</spring_stiffness>
          </dynamics>
          <use_parent_model_frame>1</use_parent_model_frame>
        </axis>
        <physics>
          <ode>
            <implicit_spring_damper>1</implicit_spring_damper>
            <cfm_damping>1</cfm_damping>
            <limit>
              <cfm>0</cfm>
              <erp>0.2</erp>
            </limit>
          </ode>
        </physics>
      </joint>
      <link name='gripper_right_finger_base_link'>
        <pose frame=''>0.3102 0.013 0.4045 -1.5708 0 -1.58825</pose>
        <inertial>
          <pose frame=''>0 0 0 0 -0 0</pose>
          <mass>0.02</mass>
          <inertia>
            <ixx>6.66667e-07</ixx>
            <ixy>0</ixy>
            <ixz>0</ixz>
            <iyy>6.66667e-07</iyy>
            <iyz>0</iyz>
            <izz>1e-06</izz>
          </inertia>
        </inertial>
        <collision name='gripper_right_finger_base_link_collision'>
          <pose frame=''>0 0 0 0 -0 0</pose>
          <geometry>
            <mesh>
              <scale>0.001 0.001 0.001</scale>
              <uri>/home/ros/catkin_ws/src/niryo_one_ros/niryo_one_description/meshes/v2/stl/G2_Clamp.STL</uri>
            </mesh>
          </geometry>
          <max_contacts>10</max_contacts>
          <surface>
            <contact>
              <ode/>
            </contact>
            <bounce/>
            <friction>
              <torsional>
                <ode/>
              </torsional>
              <ode/>
            </friction>
          </surface>
        </collision>
        <visual name='gripper_right_finger_base_link_visual'>
          <pose frame=''>0.002 0.02 0.011 3.14159 0.001593 -0.001593</pose>
          <geometry>
            <mesh>
              <scale>0.001 0.001 0.001</scale>
              <uri>/home/ros/catkin_ws/src/niryo_one_ros/niryo_one_description/meshes/v2/stl/G2_Clamp.STL</uri>
            </mesh>
          </geometry>
        </visual>
        <self_collide>0</self_collide>
        <enable_wind>0</enable_wind>
        <kinematic>0</kinematic>
      </link>
      <joint name='gripper_right_finger_base_joint' type='revolute'>
        <child>gripper_right_finger_base_link</child>
        <parent>gripper_gear_right_link</parent>
        <axis>
          <xyz>-0 0 1</xyz>
          <limit>
            <lower>-1.2</lower>
            <upper>1.2</upper>
            <effort>1000</effort>
            <velocity>0.5</velocity>
          </limit>
          <dynamics>
            <damping>0.7</damping>
            <friction>0</friction>
            <spring_reference>0</spring_reference>
            <spring_stiffness>0</spring_stiffness>
          </dynamics>
          <use_parent_model_frame>1</use_parent_model_frame>
        </axis>
        <physics>
          <ode>
            <implicit_spring_damper>1</implicit_spring_damper>
            <cfm_damping>1</cfm_damping>
            <limit>
              <cfm>0</cfm>
              <erp>0.2</erp>
            </limit>
          </ode>
        </physics>
      </joint>
      <link name='gripper_rod_left_link'>
        <pose frame=''>0.2972 -0.014 0.4045 -1.5708 0 -1.8326</pose>
        <inertial>
          <pose frame=''>0 0 0 0 -0 0</pose>
          <mass>0.25</mass>
          <inertia>
            <ixx>0.000166667</ixx>
            <ixy>0</ixy>
            <ixz>0</ixz>
            <iyy>0.000166667</iyy>
            <iyz>0</iyz>
            <izz>0.00025</izz>
          </inertia>
        </inertial>
        <collision name='gripper_rod_left_link_collision'>
          <pose frame=''>0 0 0 0 -0 0</pose>
          <geometry>
            <mesh>
              <scale>0.001 0.001 0.001</scale>
              <uri>/home/ros/catkin_ws/src/niryo_one_ros/niryo_one_description/meshes/v2/stl/G2_Rod.STL</uri>
            </mesh>
          </geometry>
          <max_contacts>10</max_contacts>
          <surface>
            <contact>
              <ode/>
            </contact>
            <bounce/>
            <friction>
              <torsional>
                <ode/>
              </torsional>
              <ode/>
            </friction>
          </surface>
        </collision>
        <visual name='gripper_rod_left_link_visual'>
          <pose frame=''>0.027 0.02 0.008 0 -0 3.14</pose>
          <geometry>
            <mesh>
              <scale>0.001 0.001 0.001</scale>
              <uri>/home/ros/catkin_ws/src/niryo_one_ros/niryo_one_description/meshes/v2/stl/G2_Rod.STL</uri>
            </mesh>
          </geometry>
        </visual>
        <self_collide>0</self_collide>
        <enable_wind>0</enable_wind>
        <kinematic>0</kinematic>
      </link>
      <joint name='gripper_rod_left_joint' type='revolute'>
        <child>gripper_rod_left_link</child>
        <parent>hand_link</parent>
        <axis>
          <xyz>-0 0 1</xyz>
          <limit>
            <lower>-1.2</lower>
            <upper>1.2</upper>
            <effort>1000</effort>
            <velocity>0.5</velocity>
          </limit>
          <dynamics>
            <damping>0.7</damping>
            <friction>0</friction>
            <spring_reference>0</spring_reference>
            <spring_stiffness>0</spring_stiffness>
          </dynamics>
          <use_parent_model_frame>1</use_parent_model_frame>
        </axis>
        <physics>
          <ode>
            <implicit_spring_damper>1</implicit_spring_damper>
            <cfm_damping>1</cfm_damping>
            <limit>
              <cfm>0</cfm>
              <erp>0.2</erp>
            </limit>
          </ode>
        </physics>
      </joint>
      <link name='gripper_rod_right_link'>
        <pose frame=''>0.2972 0 0.4045 -1.5708 -0 -1.309</pose>
        <inertial>
          <pose frame=''>0 0 0 0 -0 0</pose>
          <mass>0.25</mass>
          <inertia>
            <ixx>0.000166667</ixx>
            <ixy>0</ixy>
            <ixz>0</ixz>
            <iyy>0.000166667</iyy>
            <iyz>0</iyz>
            <izz>0.00025</izz>
          </inertia>
        </inertial>
        <collision name='gripper_rod_right_link_collision'>
          <pose frame=''>0 0 0 0 -0 0</pose>
          <geometry>
            <mesh>
              <scale>0.001 0.001 0.001</scale>
              <uri>/home/ros/catkin_ws/src/niryo_one_ros/niryo_one_description/meshes/v2/stl/G2_Rod.STL</uri>
            </mesh>
          </geometry>
          <max_contacts>10</max_contacts>
          <surface>
            <contact>
              <ode/>
            </contact>
            <bounce/>
            <friction>
              <torsional>
                <ode/>
              </torsional>
              <ode/>
            </friction>
          </surface>
        </collision>
        <visual name='gripper_rod_right_link_visual'>
          <pose frame=''>-0.027 -0.007 0.008 0 -0 0</pose>
          <geometry>
            <mesh>
              <scale>0.001 0.001 0.001</scale>
              <uri>/home/ros/catkin_ws/src/niryo_one_ros/niryo_one_description/meshes/v2/stl/G2_Rod.STL</uri>
            </mesh>
          </geometry>
        </visual>
        <self_collide>0</self_collide>
        <enable_wind>0</enable_wind>
        <kinematic>0</kinematic>
      </link>
      <joint name='gripper_rod_right_joint' type='revolute'>
        <child>gripper_rod_right_link</child>
        <parent>hand_link</parent>
        <axis>
          <xyz>-0 0 1</xyz>
          <limit>
            <lower>-1.2</lower>
            <upper>1.2</upper>
            <effort>1000</effort>
            <velocity>0.5</velocity>
          </limit>
          <dynamics>
            <damping>0.7</damping>
            <friction>0</friction>
            <spring_reference>0</spring_reference>
            <spring_stiffness>0</spring_stiffness>
          </dynamics>
          <use_parent_model_frame>1</use_parent_model_frame>
        </axis>
        <physics>
          <ode>
            <implicit_spring_damper>1</implicit_spring_damper>
            <cfm_damping>1</cfm_damping>
            <limit>
              <cfm>0</cfm>
              <erp>0.2</erp>
            </limit>
          </ode>
        </physics>
      </joint>
      <plugin name='gripper_mimic_gripper2_1' filename='libroboticsgroup_gazebo_mimic_joint_plugin.so'>
        <joint>gripper_gear_left_joint</joint>
        <mimicJoint>gripper_rod_left_joint</mimicJoint>
        <multiplier>1.186</multiplier>
        <offset>0.261799</offset>
        <robotNamespace>/</robotNamespace>
      </plugin>
      <plugin name='gripper_mimic_gripper2_2' filename='libroboticsgroup_gazebo_mimic_joint_plugin.so'>
        <joint>gripper_gear_right_joint</joint>
        <mimicJoint>gripper_rod_right_joint</mimicJoint>
        <multiplier>1.186</multiplier>
        <offset>-0.261799</offset>
        <robotNamespace>/</robotNamespace>
      </plugin>
      <plugin name='gripper_mimic_gripper2_3' filename='libroboticsgroup_gazebo_mimic_joint_plugin.so'>
        <joint>gripper_gear_left_joint</joint>
        <mimicJoint>gripper_left_finger_base_joint</mimicJoint>
        <multiplier>-1.0</multiplier>
        <offset>0</offset>
        <robotNamespace>/</robotNamespace>
      </plugin>
      <plugin name='gripper_mimic_gripper2_4' filename='libroboticsgroup_gazebo_mimic_joint_plugin.so'>
        <joint>gripper_gear_right_joint</joint>
        <mimicJoint>gripper_right_finger_base_joint</mimicJoint>
        <multiplier>-1.0</multiplier>
        <offset>0</offset>
        <robotNamespace>/</robotNamespace>
      </plugin>
      <plugin name='gazebo_grasp_fix' filename='libgazebo_grasp_fix.so'>
        <arm>
          <arm_name>niryo-arm</arm_name>
          <palm_link>hand_link</palm_link>
          <gripper_link>gripper_left_finger_base_link</gripper_link>
          <gripper_link>gripper_right_finger_base_link</gripper_link>
        </arm>
        <forces_angle_tolerance>100</forces_angle_tolerance>
        <update_rate>4</update_rate>
        <grip_count_threshold>4</grip_count_threshold>
        <max_grip_count>8</max_grip_count>
        <release_tolerance>0.005</release_tolerance>
        <disable_collisions_on_attach>0</disable_collisions_on_attach>
        <contact_topic>__default_topic__</contact_topic>
        <robotNamespace>/</robotNamespace>
      </plugin>
      <static>0</static>
      <plugin name='gazebo_ros_control' filename='libgazebo_ros_control.so'>
        <robotNamespace>/</robotNamespace>
      </plugin>
      <pose frame=''>0 0 0 0 -0 0</pose>
    </model>
    <model name='unit_box'>
      <pose frame=''>-0.458053 -0.724284 0.5 0 -0 0</pose>
      <link name='link'>
        <inertial>
          <mass>1</mass>
          <inertia>
            <ixx>0.166667</ixx>
            <ixy>0</ixy>
            <ixz>0</ixz>
            <iyy>0.166667</iyy>
            <iyz>0</iyz>
            <izz>0.166667</izz>
          </inertia>
          <pose frame=''>0 0 0 0 -0 0</pose>
        </inertial>
        <collision name='collision'>
          <geometry>
            <box>
              <size>0.999999 1 1.00001</size>
            </box>
          </geometry>
          <max_contacts>10</max_contacts>
          <surface>
            <contact>
              <ode/>
            </contact>
            <bounce/>
            <friction>
              <torsional>
                <ode/>
              </torsional>
              <ode/>
            </friction>
          </surface>
        </collision>
        <visual name='visual'>
          <geometry>
            <box>
              <size>0.999999 1 1.00001</size>
            </box>
          </geometry>
          <material>
            <script>
              <name>Gazebo/Grey</name>
              <uri>file://media/materials/scripts/gazebo.material</uri>
            </script>
          </material>
        </visual>
        <self_collide>0</self_collide>
        <enable_wind>0</enable_wind>
        <kinematic>0</kinematic>
      </link>
    </model>
    <state world_name='default'>
      <sim_time>297 29000000</sim_time>
      <real_time>327 41761401</real_time>
      <wall_time>1572519186 519501796</wall_time>
      <iterations>297029</iterations>
      <model name='ground_plane'>
        <pose frame=''>0 0 0 0 -0 0</pose>
        <scale>1 1 1</scale>
        <link name='link'>
          <pose frame=''>0 0 0 0 -0 0</pose>
          <velocity>0 0 0 0 -0 0</velocity>
          <acceleration>0 0 0 0 -0 0</acceleration>
          <wrench>0 0 0 0 -0 0</wrench>
        </link>
      </model>
      <model name='niryo_one'>
        <pose frame=''>3.4e-05 -6.4e-05 -0 -5e-06 -1e-06 0.001427</pose>
        <scale>1 1 1</scale>
        <link name='arm_link'>
          <pose frame=''>3.4e-05 -6.3e-05 0.183 1.57079 -0.786272 0.000119</pose>
          <velocity>7.7e-05 0.001771 -9e-05 3.13011 0.237075 -3.14137</velocity>
          <acceleration>0.156446 3.53375 -0.174642 -0.924036 1.40554 2.78609</acceleration>
          <wrench>0.062578 1.4135 -0.069857 0 -0 0</wrench>
        </link>
        <link name='elbow_link'>
          <pose frame=''>0.14848 -4.5e-05 0.331715 1.57079 1.08084 0.000108</pose>
          <velocity>2.31847 0.003551 -2.27876 3.1309 0.976281 -3.14141</velocity>
          <acceleration>0.156852 6.86724 -0.180577 0 -0 0</acceleration>
          <wrench>0.062741 2.7469 -0.072231 0 -0 0</wrench>
        </link>
        <link name='forearm_link'>
          <pose frame=''>0.194489 -4e-05 0.309211 2.65178 -0.011804 1.54982</pose>
          <velocity>2.13 0.003331 -2.66826 1.57694 0.963534 1.55073</velocity>
          <acceleration>0.166521 6.57077 -0.191457 -0.023877 -0.057612 -1.6332</acceleration>
          <wrench>0.066608 2.62831 -0.076583 0 -0 0</wrench>
        </link>
        <link name='gripper_gear_left_link'>
          <pose frame=''>0.266256 -0.01516 0.09476 -2.8589 -1.17465 -1.85439</pose>
          <velocity>0.001205 0.870278 -3.45592 0.835361 0.971043 1.45661</velocity>
          <acceleration>0.215343 3.57113 -0.22287 -2.26737 -0.291395 2.91454</acceleration>
          <wrench>0.053836 0.892783 -0.055718 0 -0 0</wrench>
        </link>
        <link name='gripper_gear_right_link'>
          <pose frame=''>0.266639 0.00386 0.09499 -2.84293 1.19631 -1.3135</pose>
          <velocity>0.391215 0.865049 -3.24802 1.2372 0.969803 1.50409</velocity>
          <acceleration>0.23368 3.57889 -0.255601 2.41489 -0.172332 1.0113</acceleration>
          <wrench>0.05842 0.894721 -0.0639 0 -0 0</wrench>
        </link>
        <link name='gripper_left_finger_base_link'>
          <pose frame=''>0.265884 -0.051416 0.091001 -3.03371 0.029487 -1.58937</pose>
          <velocity>-0.773955 0.90687 -3.82824 1.96622 0.970157 1.58924</velocity>
          <acceleration>-4.09797 0.257627 35.8202 2.75254 0.843592 -2.91337</acceleration>
          <wrench>-0.081959 0.005153 0.716404 0 -0 0</wrench>
        </link>
        <link name='gripper_right_finger_base_link'>
          <pose frame=''>0.267732 0.040172 0.092074 -3.03376 -0.005943 -1.5932</pose>
          <velocity>1.10875 0.883029 -2.86713 1.23752 0.971901 1.50329</velocity>
          <acceleration>0.809179 3.15439 -5.71844 -3.04331 -0.881864 1.76364</acceleration>
          <wrench>0.016184 0.063088 -0.114369 0 -0 0</wrench>
        </link>
        <link name='gripper_rod_left_link'>
          <pose frame=''>0.268661 -0.012961 0.072905 -2.54327 -1.37853 -2.18226</pose>
          <velocity>-0.14055 1.06036 -3.45366 1.57421 0.970077 1.54341</velocity>
          <acceleration>0.21015 3.53141 -0.215568 2.67217 -1.03823 0.354489</acceleration>
          <wrench>0.052538 0.882852 -0.053892 0 -0 0</wrench>
        </link>
        <link name='gripper_rod_right_link'>
          <pose frame=''>0.268943 0.001054 0.073074 -2.46705 1.3976 -0.92536</pose>
          <velocity>0.146826 1.0565 -3.30047 1.56062 0.969931 1.54188</velocity>
          <acceleration>0.223622 3.53428 -0.239033 -1.50369 -0.317405 2.85242</acceleration>
          <wrench>0.055905 0.883571 -0.059758 0 -0 0</wrench>
        </link>
        <link name='ground_link'>
          <pose frame=''>3.4e-05 -6.4e-05 -0 -5e-06 -1e-06 0.001427</pose>
          <velocity>-1e-06 -0 -8.5e-05 -0.009511 0.000413 5e-06</velocity>
          <acceleration>-0.00115 0.000113 -0.16717 -0.12764 0.823709 -0.000405</acceleration>
          <wrench>-0.115018 0.01127 -16.717 0 -0 0</wrench>
        </link>
        <link name='hand_link'>
          <pose frame=''>0.275487 0.000229 0.133442 3.03375 -0.011757 1.5503</pose>
          <velocity>0.644353 0.261025 -3.36143 1.58763 0.97023 1.54489</velocity>
          <acceleration>0.228334 3.61634 -0.230769 -2.22297 0.181308 -1.14518</acceleration>
          <wrench>0.079917 1.26572 -0.080769 0 -0 0</wrench>
        </link>
        <link name='shoulder_link'>
          <pose frame=''>3.4e-05 -6.3e-05 0.103 -4e-06 -1e-06 0.000115</pose>
          <velocity>3.8e-05 0.000979 -8.1e-05 -0.009674 0.000428 0.000116</velocity>
          <acceleration>0.077958 1.95466 -0.160381 -0.110117 -0.100754 -2.66718</acceleration>
          <wrench>0.031183 0.781862 -0.064152 0 -0 0</wrench>
        </link>
        <link name='wrist_link'>
          <pose frame=''>0.279217 -3e-05 0.150363 1.68006 1.46232 0.087645</pose>
          <velocity>0.789266 0.001376 -3.39072 1.58753 0.97023 1.54484</velocity>
          <acceleration>0.226636 3.71686 -0.196298 -1.34838 1.26132 0.71488</acceleration>
          <wrench>0.045327 0.743373 -0.03926 0 -0 0</wrench>
        </link>
      </model>
      <model name='unit_box'>
        <pose frame=''>0.273797 -5.3e-05 0.015065 0.000491 1.2e-05 -0.003061</pose>
        <scale>0.035884 0.024478 0.030117</scale>
        <link name='link'>
          <pose frame=''>0.273797 -5.3e-05 0.015065 0.000491 1.2e-05 -0.003061</pose>
          <velocity>0 0 0 0 -0 0</velocity>
          <acceleration>-0.01581 0.010849 -0.02764 -0.720171 -1.04944 -0</acceleration>
          <wrench>-0.01581 0.010849 -0.02764 0 -0 0</wrench>
        </link>
      </model>
      <light name='sun'>
        <pose frame=''>0 0 10 0 -0 0</pose>
      </light>
    </state>
    <gui fullscreen='0'>
      <camera name='user_camera'>
        <pose frame=''>0.954996 0.007235 0.151518 -0 0.172 2.964</pose>
        <view_controller>orbit</view_controller>
        <projection_type>perspective</projection_type>
      </camera>
    </gui>
  </world>
</sdf>
